Workbook

Sheet Benchmarking Data
A1: Benchmark ID | B1: Product Name | C1: Competitor Name | D1: Product Category | E1: Feature Category | F1: Feature Name | G1: Our Product Availability | H1: Competitor Availability | I1: Feature Importance Score | J1: Customer Demand Score | K1: Customer Rating | L1: Competitor Rating | M1: Our Product Price | N1: Competitor Price | O1: Pricing Model | P1: User Experience Score | Q1: Performance Score | R1: Integration Score | S1: Customer Support Score | T1: Mobile App Availability | U1: AI Capability Score | V1: Security Score | W1: Market Share % | X1: Feature Gap Score | Y1: Competitive Advantage Score | Z1: Opportunity Score | AA1: Priority Level | AB1: Recommended Action
A2: BMK-1001 | B2: CloudPulse Analytics | C2: DataGlow AI | D2: Enterprise SaaS | E2: Core Analytics | F2: Real-Time Data Streaming | G2: Available | H2: Available | I2: 6 | J2: 6 | K2: 4.6 | L2: 4.5 | M2: 50 | N2: 45 | O2: Per User/Month | P2: 8 | Q2: 9 | R2: 7 | S2: 8 | T2: Yes | U2: 6 | V2: 6 | W2: 22.5 | X2: 0 | Y2: 0.1 | Z2: 3 | AA2: Low | AB2: Monitor Market
A3: BMK-1002 | B3: CloudPulse Analytics | C3: DataGlow AI | D3: Enterprise SaaS | E3: Core Analytics | F3: Custom Dashboard Builder | G3: Available | H3: Partial | I3: 6 | J3: 5 | K3: 4.3 | L3: 4.5 | M3: 50 | N3: 45 | O3: Per User/Month | P3: 8 | Q3: 9 | R3: 6 | S3: 10 | T3: Yes | U3: 7 | V3: 6 | W3: 22.5 | X3: 0 | Y3: 3.4 | Z3: 2.7 | AA3: Low | AB3: Maintain Advantage
A4: BMK-1003 | B4: CloudPulse Analytics | C4: DataGlow AI | D4: Enterprise SaaS | E4: Core Analytics | F4: Ad-Hoc Query Engine | G4: Available | H4: Not Available | I4: 8 | J4: 9 | K4: 4.8 | L4: 4.5 | M4: 50 | N4: 45 | O4: Per User/Month | P4: 8 | Q4: 8 | R4: 6 | S4: 7 | T4: Yes | U4: 6 | V4: 6 | W4: 22.5 | X4: 0 | Y4: 9.9 | Z4: 4.3 | AA4: Low | AB4: Promote & Monetize
A5: BMK-1004 | B5: CloudPulse Analytics | C5: DataGlow AI | D5: Enterprise SaaS | E5: Core Analytics | F5: Automated PDF Reporting | G5: Available | H5: Available | I5: 7 | J5: 8 | K5: 4.3 | L5: 4.5 | M5: 50 | N5: 45 | O5: Per User/Month | P5: 8 | Q5: 8 | R5: 8 | S5: 9 | T5: No | U5: 6 | V5: 6 | W5: 22.5 | X5: 0 | Y5: -0.2 | Z5: 3.8 | AA5: Low | AB5: Monitor Market
A6: BMK-1005 | B6: CloudPulse Analytics | C6: DataGlow AI | D6: Enterprise SaaS | E6: Core Analytics | F6: Data Export (CSV/XLSX/JSON) | G6: Available | H6: Not Available | I6: 7 | J6: 10 | K6: 4.2 | L6: 4.5 | M6: 50 | N6: 45 | O6: Per User/Month | P6: 9 | Q6: 10 | R6: 8 | S6: 8 | T6: Yes | U6: 4 | V6: 7 | W6: 22.5 | X6: 0 | Y6: 8.1 | Z6: 4.4 | AA6: Low | AB6: Promote & Monetize
A7: BMK-1006 | B7: CloudPulse Analytics | C7: DataGlow AI | D7: Enterprise SaaS | E7: Core Analytics | F7: Interactive Drill-Downs | G7: Available | H7: Partial | I7: 7 | J7: 8 | K7: 4.2 | L7: 4.5 | M7: 50 | N7: 45 | O7: Per User/Month | P7: 7 | Q7: 9 | R7: 7 | S7: 10 | T7: No | U7: 7 | V7: 7 | W7: 22.5 | X7: 0 | Y7: 3.9 | Z7: 3.8 | AA7: Low | AB7: Maintain Advantage
A8: BMK-1007 | B8: CloudPulse Analytics | C8: DataGlow AI | D8: Enterprise SaaS | E8: AI & Automation | F8: Predictive Anomaly Detection | G8: Available | H8: Available | I8: 6 | J8: 6 | K8: 4.7 | L8: 4.5 | M8: 50 | N8: 45 | O8: Per User/Month | P8: 10 | Q8: 9 | R8: 10 | S8: 10 | T8: Yes | U8: 10 | V8: 8 | W8: 22.5 | X8: 0 | Y8: 0.2 | Z8: 3 | AA8: Low | AB8: Monitor Market
A9: BMK-1008 | B9: CloudPulse Analytics | C9: DataGlow AI | D9: Enterprise SaaS | E9: AI & Automation | F9: Automated Insight Generation | G9: Available | H9: Available | I9: 10 | J9: 9 | K9: 4.4 | L9: 4.5 | M9: 50 | N9: 45 | O9: Per User/Month | P9: 6 | Q9: 7 | R9: 7 | S9: 8 | T9: Yes | U9: 10 | V9: 6 | W9: 22.5 | X9: 0 | Y9: -0.1 | Z9: 4.7 | AA9: Low | AB9: Monitor Market
A10: BMK-1009 | B10: CloudPulse Analytics | C10: DataGlow AI | D10: Enterprise SaaS | E10: AI & Automation | F10: Natural Language Querying (NLQ) | G10: Partial | H10: Partial | I10: 6 | J10: 9 | K10: 4.9 | L10: 4.5 | M10: 50 | N10: 45 | O10: Per User/Month | P10: 10 | Q10: 9 | R10: 10 | S10: 7 | T10: Yes | U10: 7 | V10: 8 | W10: 22.5 | X10: 0 | Y10: 0.4 | Z10: 7.8 | AA10: Medium | AB10: Monitor Market
A11: BMK-1010 | B11: CloudPulse Analytics | C11: DataGlow AI | D11: Enterprise SaaS | E11: AI & Automation | F11: Forecasting & Trend Projection | G11: Available | H11: Available | I11: 10 | J11: 7 | K11: 4.4 | L11: 4.5 | M11: 50 | N11: 45 | O11: Per User/Month | P11: 9 | Q11: 7 | R11: 8 | S11: 8 | T11: Yes | U11: 7 | V11: 8 | W11: 22.5 | X11: 0 | Y11: -0.1 | Z11: 4.1 | AA11: Low | AB11: Monitor Market
A12: BMK-1011 | B12: CloudPulse Analytics | C12: DataGlow AI | D12: Enterprise SaaS | E12: AI & Automation | F12: Smart Alerting & Triggers | G12: Available | H12: Available | I12: 9 | J12: 7 | K12: 4.7 | L12: 4.5 | M12: 50 | N12: 45 | O12: Per User/Month | P12: 10 | Q12: 7 | R12: 10 | S12: 9 | T12: Yes | U12: 7 | V12: 8 | W12: 22.5 | X12: 0 | Y12: 0.2 | Z12: 3.9 | AA12: Low | AB12: Monitor Market
A13: BMK-1012 | B13: CloudPulse Analytics | C13: DataGlow AI | D13: Enterprise SaaS | E13: Integrations & Data Pipeline | F13: REST API & Webhooks | G13: Available | H13: Available | I13: 6 | J13: 5 | K13: 4.2 | L13: 4.5 | M13: 50 | N13: 45 | O13: Per User/Month | P13: 10 | Q13: 7 | R13: 6 | S13: 10 | T13: Yes | U13: 8 | V13: 7 | W13: 22.5 | X13: 0 | Y13: -0.3 | Z13: 2.7 | AA13: Low | AB13: Monitor Market
... A131: BMK-1130 | B131: CloudPulse Analytics | C131: VeloData | D131: SMB SaaS | E131: User Experience & Mobile | F131: Custom White-Labeling | G131: Partial | H131: Partial | I131: 10 | J131: 9 | K131: 4.5 | L131: 3.8 | M131: 50 | N131: 30 | O131: Tiered | P131: 7 | Q131: 9 | R131: 8 | S131: 9 | T131: Yes | U131: 7 | V131: 9 | W131: 8.5 | X131: 0 | Y131: 0.7 | Z131: 9.4 | AA131: High | AB131: Monitor Market

Sheet Feature List
A1: Feature Category | B1: Feature Name | C1: Feature Importance Score
A2: Core Analytics | B2: Real-Time Data Streaming | C2: 6
A3: Core Analytics | B3: Custom Dashboard Builder | C3: 6
A4: Core Analytics | B4: Ad-Hoc Query Engine | C4: 8
A5: Core Analytics | B5: Automated PDF Reporting | C5: 7
A6: Core Analytics | B6: Data Export (CSV/XLSX/JSON) | C6: 7
A7: Core Analytics | B7: Interactive Drill-Downs | C7: 7
A8: AI & Automation | B8: Predictive Anomaly Detection | C8: 6
A9: AI & Automation | B9: Automated Insight Generation | C9: 10
A10: AI & Automation | B10: Natural Language Querying (NLQ) | C10: 6
A11: AI & Automation | B11: Forecasting & Trend Projection | C11: 10
A12: AI & Automation | B12: Smart Alerting & Triggers | C12: 9
A13: Integrations & Data Pipeline | B13: REST API & Webhooks | C13: 6
... A27: User Experience & Mobile | B27: Custom White-Labeling | C27: 10

Sheet Competitor List
A1: Competitor Name | B1: Product Category | C1: Pricing Model | D1: Monthly Price | E1: Annual Price | F1: Market Share | G1: Customer Rating
A2: DataGlow AI | B2: Enterprise SaaS | C2: Per User/Month | D2: 45 | E2: 450 | F2: 22.5 | G2: 4.5
A3: MetricFlow | B3: Mid-Market SaaS | C3: Flat Rate | D3: 120 | E3: 1200 | F3: 18 | G3: 4.2
A4: InsightHub | B4: Enterprise SaaS | C4: Usage-Based | D4: 85 | E4: 850 | F4: 15.5 | G4: 4
A5: ApexAnalytics | B5: Enterprise SaaS | C5: Per User/Month | D5: 60 | E5: 600 | F5: 12 | G5: 4.6
A6: VeloData | B6: SMB SaaS | C6: Tiered | D6: 30 | E6: 300 | F6: 8.5 | G6: 3.8

Sheet Data Dictionary
A1: Column Name | B1: Description
A2: Benchmark ID | B2: Unique identifier for each benchmarking record
A3: Product Name | B3: Name of our core B2B SaaS product being benchmarked
A4: Competitor Name | B4: Name of the competing product
A5: Product Category | B5: Market segment classification of the competitor product
A6: Feature Category | B6: Functional group to which the feature belongs
A7: Feature Name | B7: Specific product capability or feature evaluated
A8: Our Product Availability | B8: Availability status of feature in our product (Available, Partial, Not Available)
A9: Competitor Availability | B9: Availability status of feature in competitor product (Available, Partial, Not Available)
A10: Feature Importance Score | B10: Weighting score of feature importance on a scale of 1 to 10
A11: Customer Demand Score | B11: Customer request and market demand rating from 1 to 10
A12: Customer Rating | B12: Average overall customer satisfaction score for our product
... A29: Recommended Action | B29: Strategic roadmap direction based on gap analysis

Sheet Feature Scoring
A1: Benchmark ID | B1: Feature Name | C1: Feature Importance Score | D1: Our Product Availability | E1: Competitor Availability | F1: Our Feature Score | G1: Competitor Feature Score
A2: ='Benchmarking Data'!A2 -> BMK-1001 | B2: ='Benchmarking Data'!F2 -> Real-Time Data Streaming | C2: ='Benchmarking Data'!I2 -> 6 | D2: ='Benchmarking Data'!G2 -> Available | E2: ='Benchmarking Data'!H2 -> Available | F2: =IF('Benchmarking Data'!G2="Available", 'Benchmarking Data'!I2, IF('Benchmarking Data'!G2="Yes", 'Benchmarking Data'!I2, IF('Benchmarking Data'!G2="Partial", 0.5*'Benchmarking Data'!I2, 0))) -> 6 | G2: =IF('Benchmarking Data'!H2="Available", 'Benchmarking Data'!I2, IF('Benchmarking Data'!H2="Yes", 'Benchmarking Data'!I2, IF('Benchmarking Data'!H2="Partial", 0.5*'Benchmarking Data'!I2, 0))) -> 6
A3: ='Benchmarking Data'!A3 -> BMK-1002 | B3: ='Benchmarking Data'!F3 -> Custom Dashboard Builder | C3: ='Benchmarking Data'!I3 -> 6 | D3: ='Benchmarking Data'!G3 -> Available | E3: ='Benchmarking Data'!H3 -> Partial | F3: =IF('Benchmarking Data'!G3="Available", 'Benchmarking Data'!I3, IF('Benchmarking Data'!G3="Yes", 'Benchmarking Data'!I3, IF('Benchmarking Data'!G3="Partial", 0.5*'Benchmarking Data'!I3, 0))) -> 6 | G3: =IF('Benchmarking Data'!H3="Available", 'Benchmarking Data'!I3, IF('Benchmarking Data'!H3="Yes", 'Benchmarking Data'!I3, IF('Benchmarking Data'!H3="Partial", 0.5*'Benchmarking Data'!I3, 0))) -> 3
A4: ='Benchmarking Data'!A4 -> BMK-1003 | B4: ='Benchmarking Data'!F4 -> Ad-Hoc Query Engine | C4: ='Benchmarking Data'!I4 -> 8 | D4: ='Benchmarking Data'!G4 -> Available | E4: ='Benchmarking Data'!H4 -> Not Available | F4: =IF('Benchmarking Data'!G4="Available", 'Benchmarking Data'!I4, IF('Benchmarking Data'!G4="Yes", 'Benchmarking Data'!I4, IF('Benchmarking Data'!G4="Partial", 0.5*'Benchmarking Data'!I4, 0))) -> 8 | G4: =IF('Benchmarking Data'!H4="Available", 'Benchmarking Data'!I4, IF('Benchmarking Data'!H4="Yes", 'Benchmarking Data'!I4, IF('Benchmarking Data'!H4="Partial", 0.5*'Benchmarking Data'!I4, 0))) -> 0
A5: ='Benchmarking Data'!A5 -> BMK-1004 | B5: ='Benchmarking Data'!F5 -> Automated PDF Reporting | C5: ='Benchmarking Data'!I5 -> 7 | D5: ='Benchmarking Data'!G5 -> Available | E5: ='Benchmarking Data'!H5 -> Available | F5: =IF('Benchmarking Data'!G5="Available", 'Benchmarking Data'!I5, IF('Benchmarking Data'!G5="Yes", 'Benchmarking Data'!I5, IF('Benchmarking Data'!G5="Partial", 0.5*'Benchmarking Data'!I5, 0))) -> 7 | G5: =IF('Benchmarking Data'!H5="Available", 'Benchmarking Data'!I5, IF('Benchmarking Data'!H5="Yes", 'Benchmarking Data'!I5, IF('Benchmarking Data'!H5="Partial", 0.5*'Benchmarking Data'!I5, 0))) -> 7
A6: ='Benchmarking Data'!A6 -> BMK-1005 | B6: ='Benchmarking Data'!F6 -> Data Export (CSV/XLSX/JSON) | C6: ='Benchmarking Data'!I6 -> 7 | D6: ='Benchmarking Data'!G6 -> Available | E6: ='Benchmarking Data'!H6 -> Not Available | F6: =IF('Benchmarking Data'!G6="Available", 'Benchmarking Data'!I6, IF('Benchmarking Data'!G6="Yes", 'Benchmarking Data'!I6, IF('Benchmarking Data'!G6="Partial", 0.5*'Benchmarking Data'!I6, 0))) -> 7 | G6: =IF('Benchmarking Data'!H6="Available", 'Benchmarking Data'!I6, IF('Benchmarking Data'!H6="Yes", 'Benchmarking Data'!I6, IF('Benchmarking Data'!H6="Partial", 0.5*'Benchmarking Data'!I6, 0))) -> 0
A7: ='Benchmarking Data'!A7 -> BMK-1006 | B7: ='Benchmarking Data'!F7 -> Interactive Drill-Downs | C7: ='Benchmarking Data'!I7 -> 7 | D7: ='Benchmarking Data'!G7 -> Available | E7: ='Benchmarking Data'!H7 -> Partial | F7: =IF('Benchmarking Data'!G7="Available", 'Benchmarking Data'!I7, IF('Benchmarking Data'!G7="Yes", 'Benchmarking Data'!I7, IF('Benchmarking Data'!G7="Partial", 0.5*'Benchmarking Data'!I7, 0))) -> 7 | G7: =IF('Benchmarking Data'!H7="Available", 'Benchmarking Data'!I7, IF('Benchmarking Data'!H7="Yes", 'Benchmarking Data'!I7, IF('Benchmarking Data'!H7="Partial", 0.5*'Benchmarking Data'!I7, 0))) -> 3.5
A8: ='Benchmarking Data'!A8 -> BMK-1007 | B8: ='Benchmarking Data'!F8 -> Predictive Anomaly Detection | C8: ='Benchmarking Data'!I8 -> 6 | D8: ='Benchmarking Data'!G8 -> Available | E8: ='Benchmarking Data'!H8 -> Available | F8: =IF('Benchmarking Data'!G8="Available", 'Benchmarking Data'!I8, IF('Benchmarking Data'!G8="Yes", 'Benchmarking Data'!I8, IF('Benchmarking Data'!G8="Partial", 0.5*'Benchmarking Data'!I8, 0))) -> 6 | G8: =IF('Benchmarking Data'!H8="Available", 'Benchmarking Data'!I8, IF('Benchmarking Data'!H8="Yes", 'Benchmarking Data'!I8, IF('Benchmarking Data'!H8="Partial", 0.5*'Benchmarking Data'!I8, 0))) -> 6
A9: ='Benchmarking Data'!A9 -> BMK-1008 | B9: ='Benchmarking Data'!F9 -> Automated Insight Generation | C9: ='Benchmarking Data'!I9 -> 10 | D9: ='Benchmarking Data'!G9 -> Available | E9: ='Benchmarking Data'!H9 -> Available | F9: =IF('Benchmarking Data'!G9="Available", 'Benchmarking Data'!I9, IF('Benchmarking Data'!G9="Yes", 'Benchmarking Data'!I9, IF('Benchmarking Data'!G9="Partial", 0.5*'Benchmarking Data'!I9, 0))) -> 10 | G9: =IF('Benchmarking Data'!H9="Available", 'Benchmarking Data'!I9, IF('Benchmarking Data'!H9="Yes", 'Benchmarking Data'!I9, IF('Benchmarking Data'!H9="Partial", 0.5*'Benchmarking Data'!I9, 0))) -> 10
A10: ='Benchmarking Data'!A10 -> BMK-1009 | B10: ='Benchmarking Data'!F10 -> Natural Language Querying (NLQ) | C10: ='Benchmarking Data'!I10 -> 6 | D10: ='Benchmarking Data'!G10 -> Partial | E10: ='Benchmarking Data'!H10 -> Partial | F10: =IF('Benchmarking Data'!G10="Available", 'Benchmarking Data'!I10, IF('Benchmarking Data'!G10="Yes", 'Benchmarking Data'!I10, IF('Benchmarking Data'!G10="Partial", 0.5*'Benchmarking Data'!I10, 0))) -> 3 | G10: =IF('Benchmarking Data'!H10="Available", 'Benchmarking Data'!I10, IF('Benchmarking Data'!H10="Yes", 'Benchmarking Data'!I10, IF('Benchmarking Data'!H10="Partial", 0.5*'Benchmarking Data'!I10, 0))) -> 3
A11: ='Benchmarking Data'!A11 -> BMK-1010 | B11: ='Benchmarking Data'!F11 -> Forecasting & Trend Projection | C11: ='Benchmarking Data'!I11 -> 10 | D11: ='Benchmarking Data'!G11 -> Available | E11: ='Benchmarking Data'!H11 -> Available | F11: =IF('Benchmarking Data'!G11="Available", 'Benchmarking Data'!I11, IF('Benchmarking Data'!G11="Yes", 'Benchmarking Data'!I11, IF('Benchmarking Data'!G11="Partial", 0.5*'Benchmarking Data'!I11, 0))) -> 10 | G11: =IF('Benchmarking Data'!H11="Available", 'Benchmarking Data'!I11, IF('Benchmarking Data'!H11="Yes", 'Benchmarking Data'!I11, IF('Benchmarking Data'!H11="Partial", 0.5*'Benchmarking Data'!I11, 0))) -> 10
A12: ='Benchmarking Data'!A12 -> BMK-1011 | B12: ='Benchmarking Data'!F12 -> Smart Alerting & Triggers | C12: ='Benchmarking Data'!I12 -> 9 | D12: ='Benchmarking Data'!G12 -> Available | E12: ='Benchmarking Data'!H12 -> Available | F12: =IF('Benchmarking Data'!G12="Available", 'Benchmarking Data'!I12, IF('Benchmarking Data'!G12="Yes", 'Benchmarking Data'!I12, IF('Benchmarking Data'!G12="Partial", 0.5*'Benchmarking Data'!I12, 0))) -> 9 | G12: =IF('Benchmarking Data'!H12="Available", 'Benchmarking Data'!I12, IF('Benchmarking Data'!H12="Yes", 'Benchmarking Data'!I12, IF('Benchmarking Data'!H12="Partial", 0.5*'Benchmarking Data'!I12, 0))) -> 9
A13: ='Benchmarking Data'!A13 -> BMK-1012 | B13: ='Benchmarking Data'!F13 -> REST API & Webhooks | C13: ='Benchmarking Data'!I13 -> 6 | D13: ='Benchmarking Data'!G13 -> Available | E13: ='Benchmarking Data'!H13 -> Available | F13: =IF('Benchmarking Data'!G13="Available", 'Benchmarking Data'!I13, IF('Benchmarking Data'!G13="Yes", 'Benchmarking Data'!I13, IF('Benchmarking Data'!G13="Partial", 0.5*'Benchmarking Data'!I13, 0))) -> 6 | G13: =IF('Benchmarking Data'!H13="Available", 'Benchmarking Data'!I13, IF('Benchmarking Data'!H13="Yes", 'Benchmarking Data'!I13, IF('Benchmarking Data'!H13="Partial", 0.5*'Benchmarking Data'!I13, 0))) -> 6
... A131: ='Benchmarking Data'!A131 -> BMK-1130 | B131: ='Benchmarking Data'!F131 -> Custom White-Labeling | C131: ='Benchmarking Data'!I131 -> 10 | D131: ='Benchmarking Data'!G131 -> Partial | E131: ='Benchmarking Data'!H131 -> Partial | F131: =IF('Benchmarking Data'!G131="Available", 'Benchmarking Data'!I131, IF('Benchmarking Data'!G131="Yes", 'Benchmarking Data'!I131, IF('Benchmarking Data'!G131="Partial", 0.5*'Benchmarking Data'!I131, 0))) -> 5 | G131: =IF('Benchmarking Data'!H131="Available", 'Benchmarking Data'!I131, IF('Benchmarking Data'!H131="Yes", 'Benchmarking Data'!I131, IF('Benchmarking Data'!H131="Partial", 0.5*'Benchmarking Data'!I131, 0))) -> 5

Sheet KPI Calculations
A1: KPI Metric | B1: Calculated Value | C1: Unit / Format
A2: Feature Coverage % | B2: =COUNTIF('Benchmarking Data'!G2:G131, "Available")/COUNTA('Benchmarking Data'!G2:G131) -> 0.72307692 | C2: Percentage
A3: Price Competitiveness Index | B3: =AVERAGE('Benchmarking Data'!M2:M131)/AVERAGE('Benchmarking Data'!N2:N131) -> 0.73529412 | C3: Ratio
A4: Customer Rating Index | B4: =AVERAGE('Benchmarking Data'!K2:K131)/AVERAGE('Benchmarking Data'!L2:L131) -> 1.0514036 | C4: Ratio
A5: Market Gap Index | B5: =AVERAGE('Benchmarking Data'!X2:X131) -> 0.26538462 | C5: Score (0-10)
A6: Average Customer Rating | B6: =AVERAGE('Benchmarking Data'!K2:K131) -> 4.4369231 | C6: Rating (1-5)
A7: Average Competitor Rating | B7: =AVERAGE('Benchmarking Data'!L2:L131) -> 4.22 | C7: Rating (1-5)
A8: Average Opportunity Score | B8: =AVERAGE('Benchmarking Data'!Z2:Z131) -> 4.7330769 | C8: Score
A9: Average Competitive Advantage Score | B9: =AVERAGE('Benchmarking Data'!Y2:Y131) -> 3.8215385 | C9: Score

Sheet Gap Analysis
A1: Feature Name | B1: Our Feature Score | C1: Best Competitor Score | D1: Gap Status | E1: Gap Category | F1: Priority Level
A2: ='Feature List'!B2 -> Real-Time Data Streaming | B2: =AVERAGEIF('Feature Scoring'!B2:B131, 'Feature List'!B2, 'Feature Scoring'!F2:F131) -> 6 | C2: =MAX('Feature Scoring'!G2:G131, 'Feature Scoring'!B2:B131, 'Feature List'!B2) -> 10 | D2: =IF(C2>B2, "Gap", "No Gap") -> Gap | E2: =IF(D2="No Gap", "None", IF((C2-B2)*'Feature List'!C2>=15, "Critical", IF((C2-B2)*'Feature List'!C2>=7, "Moderate", "Low"))) -> Critical | F2: =IF(E2="Critical", "High", IF(E2="Moderate", "Medium", "Low")) -> High
A3: ='Feature List'!B3 -> Custom Dashboard Builder | B3: =AVERAGEIF('Feature Scoring'!B2:B131, 'Feature List'!B3, 'Feature Scoring'!F2:F131) -> 4.8 | C3: =MAX('Feature Scoring'!G3:G132, 'Feature Scoring'!B3:B132, 'Feature List'!B3) -> 10 | D3: =IF(C3>B3, "Gap", "No Gap") -> Gap | E3: =IF(D3="No Gap", "None", IF((C3-B3)*'Feature List'!C3>=15, "Critical", IF((C3-B3)*'Feature List'!C3>=7, "Moderate", "Low"))) -> Critical | F3: =IF(E3="Critical", "High", IF(E3="Moderate", "Medium", "Low")) -> High
A4: ='Feature List'!B4 -> Ad-Hoc Query Engine | B4: =AVERAGEIF('Feature Scoring'!B2:B131, 'Feature List'!B4, 'Feature Scoring'!F2:F131) -> 6.4 | C4: =MAX('Feature Scoring'!G4:G133, 'Feature Scoring'!B4:B133, 'Feature List'!B4) -> 10 | D4: =IF(C4>B4, "Gap", "No Gap") -> Gap | E4: =IF(D4="No Gap", "None", IF((C4-B4)*'Feature List'!C4>=15, "Critical", IF((C4-B4)*'Feature List'!C4>=7, "Moderate", "Low"))) -> Critical | F4: =IF(E4="Critical", "High", IF(E4="Moderate", "Medium", "Low")) -> High
A5: ='Feature List'!B5 -> Automated PDF Reporting | B5: =AVERAGEIF('Feature Scoring'!B2:B131, 'Feature List'!B5, 'Feature Scoring'!F2:F131) -> 7 | C5: =MAX('Feature Scoring'!G5:G134, 'Feature Scoring'!B5:B134, 'Feature List'!B5) -> 10 | D5: =IF(C5>B5, "Gap", "No Gap") -> Gap | E5: =IF(D5="No Gap", "None", IF((C5-B5)*'Feature List'!C5>=15, "Critical", IF((C5-B5)*'Feature List'!C5>=7, "Moderate", "Low"))) -> Critical | F5: =IF(E5="Critical", "High", IF(E5="Moderate", "Medium", "Low")) -> High
A6: ='Feature List'!B6 -> Data Export (CSV/XLSX/JSON) | B6: =AVERAGEIF('Feature Scoring'!B2:B131, 'Feature List'!B6, 'Feature Scoring'!F2:F131) -> 6.3 | C6: =MAX('Feature Scoring'!G6:G135, 'Feature Scoring'!B6:B135, 'Feature List'!B6) -> 10 | D6: =IF(C6>B6, "Gap", "No Gap") -> Gap | E6: =IF(D6="No Gap", "None", IF((C6-B6)*'Feature List'!C6>=15, "Critical", IF((C6-B6)*'Feature List'!C6>=7, "Moderate", "Low"))) -> Critical | F6: =IF(E6="Critical", "High", IF(E6="Moderate", "Medium", "Low")) -> High
A7: ='Feature List'!B7 -> Interactive Drill-Downs | B7: =AVERAGEIF('Feature Scoring'!B2:B131, 'Feature List'!B7, 'Feature Scoring'!F2:F131) -> 5.6 | C7: =MAX('Feature Scoring'!G7:G136, 'Feature Scoring'!B7:B136, 'Feature List'!B7) -> 10 | D7: =IF(C7>B7, "Gap", "No Gap") -> Gap | E7: =IF(D7="No Gap", "None", IF((C7-B7)*'Feature List'!C7>=15, "Critical", IF((C7-B7)*'Feature List'!C7>=7, "Moderate", "Low"))) -> Critical | F7: =IF(E7="Critical", "High", IF(E7="Moderate", "Medium", "Low")) -> High
A8: ='Feature List'!B8 -> Predictive Anomaly Detection | B8: =AVERAGEIF('Feature Scoring'!B2:B131, 'Feature List'!B8, 'Feature Scoring'!F2:F131) -> 4.8 | C8: =MAX('Feature Scoring'!G8:G137, 'Feature Scoring'!B8:B137, 'Feature List'!B8) -> 10 | D8: =IF(C8>B8, "Gap", "No Gap") -> Gap | E8: =IF(D8="No Gap", "None", IF((C8-B8)*'Feature List'!C8>=15, "Critical", IF((C8-B8)*'Feature List'!C8>=7, "Moderate", "Low"))) -> Critical | F8: =IF(E8="Critical", "High", IF(E8="Moderate", "Medium", "Low")) -> High
A9: ='Feature List'!B9 -> Automated Insight Generation | B9: =AVERAGEIF('Feature Scoring'!B2:B131, 'Feature List'!B9, 'Feature Scoring'!F2:F131) -> 9 | C9: =MAX('Feature Scoring'!G9:G138, 'Feature Scoring'!B9:B138, 'Feature List'!B9) -> 10 | D9: =IF(C9>B9, "Gap", "No Gap") -> Gap | E9: =IF(D9="No Gap", "None", IF((C9-B9)*'Feature List'!C9>=15, "Critical", IF((C9-B9)*'Feature List'!C9>=7, "Moderate", "Low"))) -> Moderate | F9: =IF(E9="Critical", "High", IF(E9="Moderate", "Medium", "Low")) -> Medium
A10: ='Feature List'!B10 -> Natural Language Querying (NLQ) | B10: =AVERAGEIF('Feature Scoring'!B2:B131, 'Feature List'!B10, 'Feature Scoring'!F2:F131) -> 4.8 | C10: =MAX('Feature Scoring'!G10:G139, 'Feature Scoring'!B10:B139, 'Feature List'!B10) -> 10 | D10: =IF(C10>B10, "Gap", "No Gap") -> Gap | E10: =IF(D10="No Gap", "None", IF((C10-B10)*'Feature List'!C10>=15, "Critical", IF((C10-B10)*'Feature List'!C10>=7, "Moderate", "Low"))) -> Critical | F10: =IF(E10="Critical", "High", IF(E10="Moderate", "Medium", "Low")) -> High
A11: ='Feature List'!B11 -> Forecasting & Trend Projection | B11: =AVERAGEIF('Feature Scoring'!B2:B131, 'Feature List'!B11, 'Feature Scoring'!F2:F131) -> 10 | C11: =MAX('Feature Scoring'!G11:G140, 'Feature Scoring'!B11:B140, 'Feature List'!B11) -> 10 | D11: =IF(C11>B11, "Gap", "No Gap") -> No Gap | E11: =IF(D11="No Gap", "None", IF((C11-B11)*'Feature List'!C11>=15, "Critical", IF((C11-B11)*'Feature List'!C11>=7, "Moderate", "Low"))) -> None | F11: =IF(E11="Critical", "High", IF(E11="Moderate", "Medium", "Low")) -> Low
A12: ='Feature List'!B12 -> Smart Alerting & Triggers | B12: =AVERAGEIF('Feature Scoring'!B2:B131, 'Feature List'!B12, 'Feature Scoring'!F2:F131) -> 8.1 | C12: =MAX('Feature Scoring'!G12:G141, 'Feature Scoring'!B12:B141, 'Feature List'!B12) -> 10 | D12: =IF(C12>B12, "Gap", "No Gap") -> Gap | E12: =IF(D12="No Gap", "None", IF((C12-B12)*'Feature List'!C12>=15, "Critical", IF((C12-B12)*'Feature List'!C12>=7, "Moderate", "Low"))) -> Critical | F12: =IF(E12="Critical", "High", IF(E12="Moderate", "Medium", "Low")) -> High
A13: ='Feature List'!B13 -> REST API & Webhooks | B13: =AVERAGEIF('Feature Scoring'!B2:B131, 'Feature List'!B13, 'Feature Scoring'!F2:F131) -> 6 | C13: =MAX('Feature Scoring'!G13:G142, 'Feature Scoring'!B13:B142, 'Feature List'!B13) -> 10 | D13: =IF(C13>B13, "Gap", "No Gap") -> Gap | E13: =IF(D13="No Gap", "None", IF((C13-B13)*'Feature List'!C13>=15, "Critical", IF((C13-B13)*'Feature List'!C13>=7, "Moderate", "Low"))) -> Critical | F13: =IF(E13="Critical", "High", IF(E13="Moderate", "Medium", "Low")) -> High
A14: ='Feature List'!B14 -> Pre-built Salesforce Connector | B14: =AVERAGEIF('Feature Scoring'!B2:B131, 'Feature List'!B14, 'Feature Scoring'!F2:F131) -> 5.4 | C14: =MAX('Feature Scoring'!G14:G143, 'Feature Scoring'!B14:B143, 'Feature List'!B14) -> 10 | D14: =IF(C14>B14, "Gap", "No Gap") -> Gap | E14: =IF(D14="No Gap", "None", IF((C14-B14)*'Feature List'!C14>=15, "Critical", IF((C14-B14)*'Feature List'!C14>=7, "Moderate", "Low"))) -> Critical | F14: =IF(E14="Critical", "High", IF(E14="Moderate", "Medium", "Low")) -> High
A15: ='Feature List'!B15 -> Snowflake & BigQuery Sync | B15: =AVERAGEIF('Feature Scoring'!B2:B131, 'Feature List'!B15, 'Feature Scoring'!F2:F131) -> 4.8 | C15: =MAX('Feature Scoring'!G15:G144, 'Feature Scoring'!B15:B144, 'Feature List'!B15) -> 10 | D15: =IF(C15>B15, "Gap", "No Gap") -> Gap | E15: =IF(D15="No Gap", "None", IF((C15-B15)*'Feature List'!C15>=15, "Critical", IF((C15-B15)*'Feature List'!C15>=7, "Moderate", "Low"))) -> Critical | F15: =IF(E15="Critical", "High", IF(E15="Moderate", "Medium", "Low")) -> High
A16: ='Feature List'!B16 -> Zapier & Make Integration | B16: =AVERAGEIF('Feature Scoring'!B2:B131, 'Feature List'!B16, 'Feature Scoring'!F2:F131) -> 6.3 | C16: =MAX('Feature Scoring'!G16:G145, 'Feature Scoring'!B16:B145, 'Feature List'!B16) -> 10 | D16: =IF(C16>B16, "Gap", "No Gap") -> Gap | E16: =IF(D16="No Gap", "None", IF((C16-B16)*'Feature List'!C16>=15, "Critical", IF((C16-B16)*'Feature List'!C16>=7, "Moderate", "Low"))) -> Critical | F16: =IF(E16="Critical", "High", IF(E16="Moderate", "Medium", "Low")) -> High
A17: ='Feature List'!B17 -> Custom ETL Scripting Support | B17: =AVERAGEIF('Feature Scoring'!B2:B131, 'Feature List'!B17, 'Feature Scoring'!F2:F131) -> 5.6 | C17: =MAX('Feature Scoring'!G17:G146, 'Feature Scoring'!B17:B146, 'Feature List'!B17) -> 10 | D17: =IF(C17>B17, "Gap", "No Gap") -> Gap | E17: =IF(D17="No Gap", "None", IF((C17-B17)*'Feature List'!C17>=15, "Critical", IF((C17-B17)*'Feature List'!C17>=7, "Moderate", "Low"))) -> Critical | F17: =IF(E17="Critical", "High", IF(E17="Moderate", "Medium", "Low")) -> High
A18: ='Feature List'!B18 -> Role-Based Access Control (RBAC) | B18: =AVERAGEIF('Feature Scoring'!B2:B131, 'Feature List'!B18, 'Feature Scoring'!F2:F131) -> 10 | C18: =MAX('Feature Scoring'!G18:G147, 'Feature Scoring'!B18:B147, 'Feature List'!B18) -> 10 | D18: =IF(C18>B18, "Gap", "No Gap") -> No Gap | E18: =IF(D18="No Gap", "None", IF((C18-B18)*'Feature List'!C18>=15, "Critical", IF((C18-B18)*'Feature List'!C18>=7, "Moderate", "Low"))) -> None | F18: =IF(E18="Critical", "High", IF(E18="Moderate", "Medium", "Low")) -> Low
A19: ='Feature List'!B19 -> SOC2 Type II Compliance | B19: =AVERAGEIF('Feature Scoring'!B2:B131, 'Feature List'!B19, 'Feature Scoring'!F2:F131) -> 8 | C19: =MAX('Feature Scoring'!G19:G148, 'Feature Scoring'!B19:B148, 'Feature List'!B19) -> 10 | D19: =IF(C19>B19, "Gap", "No Gap") -> Gap | E19: =IF(D19="No Gap", "None", IF((C19-B19)*'Feature List'!C19>=15, "Critical", IF((C19-B19)*'Feature List'!C19>=7, "Moderate", "Low"))) -> Critical | F19: =IF(E19="Critical", "High", IF(E19="Moderate", "Medium", "Low")) -> High
A20: ='Feature List'!B20 -> Single Sign-On (SSO / SAML) | B20: =AVERAGEIF('Feature Scoring'!B2:B131, 'Feature List'!B20, 'Feature Scoring'!F2:F131) -> 4.8 | C20: =MAX('Feature Scoring'!G20:G149, 'Feature Scoring'!B20:B149, 'Feature List'!B20) -> 10 | D20: =IF(C20>B20, "Gap", "No Gap") -> Gap | E20: =IF(D20="No Gap", "None", IF((C20-B20)*'Feature List'!C20>=15, "Critical", IF((C20-B20)*'Feature List'!C20>=7, "Moderate", "Low"))) -> Critical | F20: =IF(E20="Critical", "High", IF(E20="Moderate", "Medium", "Low")) -> High
A21: ='Feature List'!B21 -> Data Masking & Encryption at Rest | B21: =AVERAGEIF('Feature Scoring'!B2:B131, 'Feature List'!B21, 'Feature Scoring'!F2:F131) -> 9 | C21: =MAX('Feature Scoring'!G21:G150, 'Feature Scoring'!B21:B150, 'Feature List'!B21) -> 10 | D21: =IF(C21>B21, "Gap", "No Gap") -> Gap | E21: =IF(D21="No Gap", "None", IF((C21-B21)*'Feature List'!C21>=15, "Critical", IF((C21-B21)*'Feature List'!C21>=7, "Moderate", "Low"))) -> Moderate | F21: =IF(E21="Critical", "High", IF(E21="Moderate", "Medium", "Low")) -> Medium
A22: ='Feature List'!B22 -> Audit Logging & Activity Trails | B22: =AVERAGEIF('Feature Scoring'!B2:B131, 'Feature List'!B22, 'Feature Scoring'!F2:F131) -> 4.2 | C22: =MAX('Feature Scoring'!G22:G151, 'Feature Scoring'!B22:B151, 'Feature List'!B22) -> 10 | D22: =IF(C22>B22, "Gap", "No Gap") -> Gap | E22: =IF(D22="No Gap", "None", IF((C22-B22)*'Feature List'!C22>=15, "Critical", IF((C22-B22)*'Feature List'!C22>=7, "Moderate", "Low"))) -> Critical | F22: =IF(E22="Critical", "High", IF(E22="Moderate", "Medium", "Low")) -> High
A23: ='Feature List'!B23 -> Native iOS & Android App | B23: =AVERAGEIF('Feature Scoring'!B2:B131, 'Feature List'!B23, 'Feature Scoring'!F2:F131) -> 9 | C23: =MAX('Feature Scoring'!G23:G152, 'Feature Scoring'!B23:B152, 'Feature List'!B23) -> 10 | D23: =IF(C23>B23, "Gap", "No Gap") -> Gap | E23: =IF(D23="No Gap", "None", IF((C23-B23)*'Feature List'!C23>=15, "Critical", IF((C23-B23)*'Feature List'!C23>=7, "Moderate", "Low"))) -> Moderate | F23: =IF(E23="Critical", "High", IF(E23="Moderate", "Medium", "Low")) -> Medium
A24: ='Feature List'!B24 -> Dark Mode / Custom Themes | B24: =AVERAGEIF('Feature Scoring'!B2:B131, 'Feature List'!B24, 'Feature Scoring'!F2:F131) -> 6.3 | C24: =MAX('Feature Scoring'!G24:G153, 'Feature Scoring'!B24:B153, 'Feature List'!B24) -> 10 | D24: =IF(C24>B24, "Gap", "No Gap") -> Gap | E24: =IF(D24="No Gap", "None", IF((C24-B24)*'Feature List'!C24>=15, "Critical", IF((C24-B24)*'Feature List'!C24>=7, "Moderate", "Low"))) -> Critical | F24: =IF(E24="Critical", "High", IF(E24="Moderate", "Medium", "Low")) -> High
A25: ='Feature List'!B25 -> Collaborative Comments & Tagging | B25: =AVERAGEIF('Feature Scoring'!B2:B131, 'Feature List'!B25, 'Feature Scoring'!F2:F131) -> 5.6 | C25: =MAX('Feature Scoring'!G25:G154, 'Feature Scoring'!B25:B154, 'Feature List'!B25) -> 10 | D25: =IF(C25>B25, "Gap", "No Gap") -> Gap | E25: =IF(D25="No Gap", "None", IF((C25-B25)*'Feature List'!C25>=15, "Critical", IF((C25-B25)*'Feature List'!C25>=7, "Moderate", "Low"))) -> Critical | F25: =IF(E25="Critical", "High", IF(E25="Moderate", "Medium", "Low")) -> High
A26: ='Feature List'!B26 -> Multi-Language Localization | B26: =AVERAGEIF('Feature Scoring'!B2:B131, 'Feature List'!B26, 'Feature Scoring'!F2:F131) -> 8.1 | C26: =MAX('Feature Scoring'!G26:G155, 'Feature Scoring'!B26:B155, 'Feature List'!B26) -> 10 | D26: =IF(C26>B26, "Gap", "No Gap") -> Gap | E26: =IF(D26="No Gap", "None", IF((C26-B26)*'Feature List'!C26>=15, "Critical", IF((C26-B26)*'Feature List'!C26>=7, "Moderate", "Low"))) -> Critical | F26: =IF(E26="Critical", "High", IF(E26="Moderate", "Medium", "Low")) -> High
A27: ='Feature List'!B27 -> Custom White-Labeling | B27: =AVERAGEIF('Feature Scoring'!B2:B131, 'Feature List'!B27, 'Feature Scoring'!F2:F131) -> 9 | C27: =MAX('Feature Scoring'!G27:G156, 'Feature Scoring'!B27:B156, 'Feature List'!B27) -> 10 | D27: =IF(C27>B27, "Gap", "No Gap") -> Gap | E27: =IF(D27="No Gap", "None", IF((C27-B27)*'Feature List'!C27>=15, "Critical", IF((C27-B27)*'Feature List'!C27>=7, "Moderate", "Low"))) -> Moderate | F27: =IF(E27="Critical", "High", IF(E27="Moderate", "Medium", "Low")) -> Medium

Sheet Competitor Comparison
A1: Competitor Name | B1: Average Feature Score | C1: Feature Coverage % | D1: Average Customer Rating | E1: Average User Experience Score | F1: Average Performance Score | G1: Average Integration Score | H1: Average Customer Support Score | I1: Average AI Capability Score | J1: Average Security Score | K1: Average Opportunity Score | L1: Average Competitive Advantage Score | M1: Average Market Share % | N1: Average Product Price
A2: ='Competitor List'!A2 -> DataGlow AI | B2: =AVERAGEIF('Benchmarking Data'!C2:C131, 'Competitor List'!A2, 'Feature Scoring'!G2:G131) -> 5.2115385 | C2: =COUNTIFS('Benchmarking Data'!C2:C131, 'Competitor List'!A2, 'Benchmarking Data'!H2:H131, "Available")/COUNTIF('Benchmarking Data'!C2:C131, 'Competitor List'!A2) -> 0.57692308 | D2: =AVERAGEIF('Benchmarking Data'!C2:C131, 'Competitor List'!A2, 'Benchmarking Data'!L2:L131) -> 4.5 | E2: =AVERAGEIF('Benchmarking Data'!C2:C131, 'Competitor List'!A2, 'Benchmarking Data'!P2:P131) -> 7.9230769 | F2: =AVERAGEIF('Benchmarking Data'!C2:C131, 'Competitor List'!A2, 'Benchmarking Data'!Q2:Q131) -> 8.3846154 | G2: =AVERAGEIF('Benchmarking Data'!C2:C131, 'Competitor List'!A2, 'Benchmarking Data'!R2:R131) -> 7.8461538 | H2: =AVERAGEIF('Benchmarking Data'!C2:C131, 'Competitor List'!A2, 'Benchmarking Data'!S2:S131) -> 8.3846154 | I2: =AVERAGEIF('Benchmarking Data'!C2:C131, 'Competitor List'!A2, 'Benchmarking Data'!U2:U131) -> 6.3076923 | J2: =AVERAGEIF('Benchmarking Data'!C2:C131, 'Competitor List'!A2, 'Benchmarking Data'!V2:V131) -> 7.4615385 | K2: =AVERAGEIF('Benchmarking Data'!C2:C131, 'Competitor List'!A2, 'Benchmarking Data'!Z2:Z131) -> 4.2346154 | L2: =AVERAGEIF('Benchmarking Data'!C2:C131, 'Competitor List'!A2, 'Benchmarking Data'!Y2:Y131) -> 2.4884615 | M2: =AVERAGEIF('Benchmarking Data'!C2:C131, 'Competitor List'!A2, 'Benchmarking Data'!W2:W131) -> 22.5 | N2: =AVERAGEIF('Benchmarking Data'!C2:C131, 'Competitor List'!A2, 'Benchmarking Data'!N2:N131) -> 45
A3: ='Competitor List'!A3 -> MetricFlow | B3: =AVERAGEIF('Benchmarking Data'!C2:C131, 'Competitor List'!A3, 'Feature Scoring'!G2:G131) -> 2.8653846 | C3: =COUNTIFS('Benchmarking Data'!C2:C131, 'Competitor List'!A3, 'Benchmarking Data'!H2:H131, "Available")/COUNTIF('Benchmarking Data'!C2:C131, 'Competitor List'!A3) -> 0.15384615 | D3: =AVERAGEIF('Benchmarking Data'!C2:C131, 'Competitor List'!A3, 'Benchmarking Data'!L2:L131) -> 4.2 | E3: =AVERAGEIF('Benchmarking Data'!C2:C131, 'Competitor List'!A3, 'Benchmarking Data'!P2:P131) -> 8.0769231 | F3: =AVERAGEIF('Benchmarking Data'!C2:C131, 'Competitor List'!A3, 'Benchmarking Data'!Q2:Q131) -> 8.9615385 | G3: =AVERAGEIF('Benchmarking Data'!C2:C131, 'Competitor List'!A3, 'Benchmarking Data'!R2:R131) -> 8.0769231 | H3: =AVERAGEIF('Benchmarking Data'!C2:C131, 'Competitor List'!A3, 'Benchmarking Data'!S2:S131) -> 8.3076923 | I3: =AVERAGEIF('Benchmarking Data'!C2:C131, 'Competitor List'!A3, 'Benchmarking Data'!U2:U131) -> 6.0769231 | J3: =AVERAGEIF('Benchmarking Data'!C2:C131, 'Competitor List'!A3, 'Benchmarking Data'!V2:V131) -> 7.8076923 | K3: =AVERAGEIF('Benchmarking Data'!C2:C131, 'Competitor List'!A3, 'Benchmarking Data'!Z2:Z131) -> 4.8576923 | L3: =AVERAGEIF('Benchmarking Data'!C2:C131, 'Competitor List'!A3, 'Benchmarking Data'!Y2:Y131) -> 4.8846154 | M3: =AVERAGEIF('Benchmarking Data'!C2:C131, 'Competitor List'!A3, 'Benchmarking Data'!W2:W131) -> 18 | N3: =AVERAGEIF('Benchmarking Data'!C2:C131, 'Competitor List'!A3, 'Benchmarking Data'!N2:N131) -> 120
A4: ='Competitor List'!A4 -> InsightHub | B4: =AVERAGEIF('Benchmarking Data'!C2:C131, 'Competitor List'!A4, 'Feature Scoring'!G2:G131) -> 3.3653846 | C4: =COUNTIFS('Benchmarking Data'!C2:C131, 'Competitor List'!A4, 'Benchmarking Data'!H2:H131, "Available")/COUNTIF('Benchmarking Data'!C2:C131, 'Competitor List'!A4) -> 0.19230769 | D4: =AVERAGEIF('Benchmarking Data'!C2:C131, 'Competitor List'!A4, 'Benchmarking Data'!L2:L131) -> 4 | E4: =AVERAGEIF('Benchmarking Data'!C2:C131, 'Competitor List'!A4, 'Benchmarking Data'!P2:P131) -> 7.7692308 | F4: =AVERAGEIF('Benchmarking Data'!C2:C131, 'Competitor List'!A4, 'Benchmarking Data'!Q2:Q131) -> 8.6153846 | G4: =AVERAGEIF('Benchmarking Data'!C2:C131, 'Competitor List'!A4, 'Benchmarking Data'!R2:R131) -> 7.5769231 | H4: =AVERAGEIF('Benchmarking Data'!C2:C131, 'Competitor List'!A4, 'Benchmarking Data'!S2:S131) -> 8 | I4: =AVERAGEIF('Benchmarking Data'!C2:C131, 'Competitor List'!A4, 'Benchmarking Data'!U2:U131) -> 6.8846154 | J4: =AVERAGEIF('Benchmarking Data'!C2:C131, 'Competitor List'!A4, 'Benchmarking Data'!V2:V131) -> 8.1153846 | K4: =AVERAGEIF('Benchmarking Data'!C2:C131, 'Competitor List'!A4, 'Benchmarking Data'!Z2:Z131) -> 5.0230769 | L4: =AVERAGEIF('Benchmarking Data'!C2:C131, 'Competitor List'!A4, 'Benchmarking Data'!Y2:Y131) -> 3.9807692 | M4: =AVERAGEIF('Benchmarking Data'!C2:C131, 'Competitor List'!A4, 'Benchmarking Data'!W2:W131) -> 15.5 | N4: =AVERAGEIF('Benchmarking Data'!C2:C131, 'Competitor List'!A4, 'Benchmarking Data'!N2:N131) -> 85
A5: ='Competitor List'!A5 -> ApexAnalytics | B5: =AVERAGEIF('Benchmarking Data'!C2:C131, 'Competitor List'!A5, 'Feature Scoring'!G2:G131) -> 3.4807692 | C5: =COUNTIFS('Benchmarking Data'!C2:C131, 'Competitor List'!A5, 'Benchmarking Data'!H2:H131, "Available")/COUNTIF('Benchmarking Data'!C2:C131, 'Competitor List'!A5) -> 0.26923077 | D5: =AVERAGEIF('Benchmarking Data'!C2:C131, 'Competitor List'!A5, 'Benchmarking Data'!L2:L131) -> 4.6 | E5: =AVERAGEIF('Benchmarking Data'!C2:C131, 'Competitor List'!A5, 'Benchmarking Data'!P2:P131) -> 8.2692308 | F5: =AVERAGEIF('Benchmarking Data'!C2:C131, 'Competitor List'!A5, 'Benchmarking Data'!Q2:Q131) -> 8.6538462 | G5: =AVERAGEIF('Benchmarking Data'!C2:C131, 'Competitor List'!A5, 'Benchmarking Data'!R2:R131) -> 7.7307692 | H5: =AVERAGEIF('Benchmarking Data'!C2:C131, 'Competitor List'!A5, 'Benchmarking Data'!S2:S131) -> 8.5384615 | I5: =AVERAGEIF('Benchmarking Data'!C2:C131, 'Competitor List'!A5, 'Benchmarking Data'!U2:U131) -> 6.2692308 | J5: =AVERAGEIF('Benchmarking Data'!C2:C131, 'Competitor List'!A5, 'Benchmarking Data'!V2:V131) -> 7.8076923 | K5: =AVERAGEIF('Benchmarking Data'!C2:C131, 'Competitor List'!A5, 'Benchmarking Data'!Z2:Z131) -> 4.8461538 | L5: =AVERAGEIF('Benchmarking Data'!C2:C131, 'Competitor List'!A5, 'Benchmarking Data'!Y2:Y131) -> 3.4653846 | M5: =AVERAGEIF('Benchmarking Data'!C2:C131, 'Competitor List'!A5, 'Benchmarking Data'!W2:W131) -> 12 | N5: =AVERAGEIF('Benchmarking Data'!C2:C131, 'Competitor List'!A5, 'Benchmarking Data'!N2:N131) -> 60
A6: ='Competitor List'!A6 -> VeloData | B6: =AVERAGEIF('Benchmarking Data'!C2:C131, 'Competitor List'!A6, 'Feature Scoring'!G2:G131) -> 3.6923077 | C6: =COUNTIFS('Benchmarking Data'!C2:C131, 'Competitor List'!A6, 'Benchmarking Data'!H2:H131, "Available")/COUNTIF('Benchmarking Data'!C2:C131, 'Competitor List'!A6) -> 0.30769231 | D6: =AVERAGEIF('Benchmarking Data'!C2:C131, 'Competitor List'!A6, 'Benchmarking Data'!L2:L131) -> 3.8 | E6: =AVERAGEIF('Benchmarking Data'!C2:C131, 'Competitor List'!A6, 'Benchmarking Data'!P2:P131) -> 7.9230769 | F6: =AVERAGEIF('Benchmarking Data'!C2:C131, 'Competitor List'!A6, 'Benchmarking Data'!Q2:Q131) -> 8.6538462 | G6: =AVERAGEIF('Benchmarking Data'!C2:C131, 'Competitor List'!A6, 'Benchmarking Data'!R2:R131) -> 8.1923077 | H6: =AVERAGEIF('Benchmarking Data'!C2:C131, 'Competitor List'!A6, 'Benchmarking Data'!S2:S131) -> 8.5384615 | I6: =AVERAGEIF('Benchmarking Data'!C2:C131, 'Competitor List'!A6, 'Benchmarking Data'!U2:U131) -> 6.6923077 | J6: =AVERAGEIF('Benchmarking Data'!C2:C131, 'Competitor List'!A6, 'Benchmarking Data'!V2:V131) -> 7.6538462 | K6: =AVERAGEIF('Benchmarking Data'!C2:C131, 'Competitor List'!A6, 'Benchmarking Data'!Z2:Z131) -> 4.7038462 | L6: =AVERAGEIF('Benchmarking Data'!C2:C131, 'Competitor List'!A6, 'Benchmarking Data'!Y2:Y131) -> 4.2884615 | M6: =AVERAGEIF('Benchmarking Data'!C2:C131, 'Competitor List'!A6, 'Benchmarking Data'!W2:W131) -> 8.5 | N6: =AVERAGEIF('Benchmarking Data'!C2:C131, 'Competitor List'!A6, 'Benchmarking Data'!N2:N131) -> 30

Sheet Feature Comparison Matrix
A1: Feature Name | B1: Our Product | C1: DataGlow AI | D1: MetricFlow | E1: InsightHub | F1: ApexAnalytics | G1: VeloData | H1: Customer Demand | I1: Business Importance | J1: Gap | K1: Priority | L1: Recommended Action
A2: ='Feature List'!B2 -> Real-Time Data Streaming | B2: {=INDEX('Benchmarking Data'!G2:G131, MATCH('Feature List'!B2, 'Benchmarking Data'!F2:F131, 0))} -> Available | C2: {=INDEX('Benchmarking Data'!H2:H131, MATCH(1, ('Benchmarking Data'!F2:F131='Feature List'!B2)*('Benchmarking Data'!C2:C131='Competitor List'!A2), 0))} -> Available | D2: {=INDEX('Benchmarking Data'!H2:H131, MATCH(1, ('Benchmarking Data'!F2:F131='Feature List'!B2)*('Benchmarking Data'!C2:C131='Competitor List'!A3), 0))} -> Available | E2: {=INDEX('Benchmarking Data'!H2:H131, MATCH(1, ('Benchmarking Data'!F2:F131='Feature List'!B2)*('Benchmarking Data'!C2:C131='Competitor List'!A4), 0))} -> Available | F2: {=INDEX('Benchmarking Data'!H2:H131, MATCH(1, ('Benchmarking Data'!F2:F131='Feature List'!B2)*('Benchmarking Data'!C2:C131='Competitor List'!A5), 0))} -> Not Available | G2: {=INDEX('Benchmarking Data'!H2:H131, MATCH(1, ('Benchmarking Data'!F2:F131='Feature List'!B2)*('Benchmarking Data'!C2:C131='Competitor List'!A6), 0))} -> Available | H2: =AVERAGEIF('Benchmarking Data'!F2:F131, 'Feature List'!B2, 'Benchmarking Data'!J2:J131) -> 5.8 | I2: ='Feature List'!C2 -> 6 | J2: =VLOOKUP('Feature List'!B2, 'Gap Analysis'!A2:F26, 4, FALSE) -> Gap | K2: =VLOOKUP('Feature List'!B2, 'Gap Analysis'!A2:F26, 6, FALSE) -> High | L2: {=INDEX('Benchmarking Data'!AB2:AB131, MATCH('Feature List'!B2, 'Benchmarking Data'!F2:F131, 0))} -> Monitor Market
A3: ='Feature List'!B3 -> Custom Dashboard Builder | B3: {=INDEX('Benchmarking Data'!G2:G131, MATCH('Feature List'!B3, 'Benchmarking Data'!F2:F131, 0))} -> Available | C3: {=INDEX('Benchmarking Data'!H2:H131, MATCH(1, ('Benchmarking Data'!F2:F131='Feature List'!B3)*('Benchmarking Data'!C2:C131='Competitor List'!A2), 0))} -> Partial | D3: {=INDEX('Benchmarking Data'!H2:H131, MATCH(1, ('Benchmarking Data'!F2:F131='Feature List'!B3)*('Benchmarking Data'!C2:C131='Competitor List'!A3), 0))} -> Partial | E3: {=INDEX('Benchmarking Data'!H2:H131, MATCH(1, ('Benchmarking Data'!F2:F131='Feature List'!B3)*('Benchmarking Data'!C2:C131='Competitor List'!A4), 0))} -> Partial | F3: {=INDEX('Benchmarking Data'!H2:H131, MATCH(1, ('Benchmarking Data'!F2:F131='Feature List'!B3)*('Benchmarking Data'!C2:C131='Competitor List'!A5), 0))} -> Partial | G3: {=INDEX('Benchmarking Data'!H2:H131, MATCH(1, ('Benchmarking Data'!F2:F131='Feature List'!B3)*('Benchmarking Data'!C2:C131='Competitor List'!A6), 0))} -> Not Available | H3: =AVERAGEIF('Benchmarking Data'!F2:F131, 'Feature List'!B3, 'Benchmarking Data'!J2:J131) -> 5.8 | I3: ='Feature List'!C3 -> 6 | J3: =VLOOKUP('Feature List'!B3, 'Gap Analysis'!A2:F26, 4, FALSE) -> Gap | K3: =VLOOKUP('Feature List'!B3, 'Gap Analysis'!A2:F26, 6, FALSE) -> High | L3: {=INDEX('Benchmarking Data'!AB2:AB131, MATCH('Feature List'!B3, 'Benchmarking Data'!F2:F131, 0))} -> Maintain Advantage
A4: ='Feature List'!B4 -> Ad-Hoc Query Engine | B4: {=INDEX('Benchmarking Data'!G2:G131, MATCH('Feature List'!B4, 'Benchmarking Data'!F2:F131, 0))} -> Available | C4: {=INDEX('Benchmarking Data'!H2:H131, MATCH(1, ('Benchmarking Data'!F2:F131='Feature List'!B4)*('Benchmarking Data'!C2:C131='Competitor List'!A2), 0))} -> Not Available | D4: {=INDEX('Benchmarking Data'!H2:H131, MATCH(1, ('Benchmarking Data'!F2:F131='Feature List'!B4)*('Benchmarking Data'!C2:C131='Competitor List'!A3), 0))} -> Not Available | E4: {=INDEX('Benchmarking Data'!H2:H131, MATCH(1, ('Benchmarking Data'!F2:F131='Feature List'!B4)*('Benchmarking Data'!C2:C131='Competitor List'!A4), 0))} -> Not Available | F4: {=INDEX('Benchmarking Data'!H2:H131, MATCH(1, ('Benchmarking Data'!F2:F131='Feature List'!B4)*('Benchmarking Data'!C2:C131='Competitor List'!A5), 0))} -> Partial | G4: {=INDEX('Benchmarking Data'!H2:H131, MATCH(1, ('Benchmarking Data'!F2:F131='Feature List'!B4)*('Benchmarking Data'!C2:C131='Competitor List'!A6), 0))} -> Not Available | H4: =AVERAGEIF('Benchmarking Data'!F2:F131, 'Feature List'!B4, 'Benchmarking Data'!J2:J131) -> 7.2 | I4: ='Feature List'!C4 -> 8 | J4: =VLOOKUP('Feature List'!B4, 'Gap Analysis'!A2:F26, 4, FALSE) -> Gap | K4: =VLOOKUP('Feature List'!B4, 'Gap Analysis'!A2:F26, 6, FALSE) -> High | L4: {=INDEX('Benchmarking Data'!AB2:AB131, MATCH('Feature List'!B4, 'Benchmarking Data'!F2:F131, 0))} -> Promote & Monetize
A5: ='Feature List'!B5 -> Automated PDF Reporting | B5: {=INDEX('Benchmarking Data'!G2:G131, MATCH('Feature List'!B5, 'Benchmarking Data'!F2:F131, 0))} -> Available | C5: {=INDEX('Benchmarking Data'!H2:H131, MATCH(1, ('Benchmarking Data'!F2:F131='Feature List'!B5)*('Benchmarking Data'!C2:C131='Competitor List'!A2), 0))} -> Available | D5: {=INDEX('Benchmarking Data'!H2:H131, MATCH(1, ('Benchmarking Data'!F2:F131='Feature List'!B5)*('Benchmarking Data'!C2:C131='Competitor List'!A3), 0))} -> Not Available | E5: {=INDEX('Benchmarking Data'!H2:H131, MATCH(1, ('Benchmarking Data'!F2:F131='Feature List'!B5)*('Benchmarking Data'!C2:C131='Competitor List'!A4), 0))} -> Not Available | F5: {=INDEX('Benchmarking Data'!H2:H131, MATCH(1, ('Benchmarking Data'!F2:F131='Feature List'!B5)*('Benchmarking Data'!C2:C131='Competitor List'!A5), 0))} -> Partial | G5: {=INDEX('Benchmarking Data'!H2:H131, MATCH(1, ('Benchmarking Data'!F2:F131='Feature List'!B5)*('Benchmarking Data'!C2:C131='Competitor List'!A6), 0))} -> Partial | H5: =AVERAGEIF('Benchmarking Data'!F2:F131, 'Feature List'!B5, 'Benchmarking Data'!J2:J131) -> 8.6 | I5: ='Feature List'!C5 -> 7 | J5: =VLOOKUP('Feature List'!B5, 'Gap Analysis'!A2:F26, 4, FALSE) -> Gap | K5: =VLOOKUP('Feature List'!B5, 'Gap Analysis'!A2:F26, 6, FALSE) -> High | L5: {=INDEX('Benchmarking Data'!AB2:AB131, MATCH('Feature List'!B5, 'Benchmarking Data'!F2:F131, 0))} -> Monitor Market
A6: ='Feature List'!B6 -> Data Export (CSV/XLSX/JSON) | B6: {=INDEX('Benchmarking Data'!G2:G131, MATCH('Feature List'!B6, 'Benchmarking Data'!F2:F131, 0))} -> Available | C6: {=INDEX('Benchmarking Data'!H2:H131, MATCH(1, ('Benchmarking Data'!F2:F131='Feature List'!B6)*('Benchmarking Data'!C2:C131='Competitor List'!A2), 0))} -> Not Available | D6: {=INDEX('Benchmarking Data'!H2:H131, MATCH(1, ('Benchmarking Data'!F2:F131='Feature List'!B6)*('Benchmarking Data'!C2:C131='Competitor List'!A3), 0))} -> Not Available | E6: {=INDEX('Benchmarking Data'!H2:H131, MATCH(1, ('Benchmarking Data'!F2:F131='Feature List'!B6)*('Benchmarking Data'!C2:C131='Competitor List'!A4), 0))} -> Not Available | F6: {=INDEX('Benchmarking Data'!H2:H131, MATCH(1, ('Benchmarking Data'!F2:F131='Feature List'!B6)*('Benchmarking Data'!C2:C131='Competitor List'!A5), 0))} -> Partial | G6: {=INDEX('Benchmarking Data'!H2:H131, MATCH(1, ('Benchmarking Data'!F2:F131='Feature List'!B6)*('Benchmarking Data'!C2:C131='Competitor List'!A6), 0))} -> Not Available | H6: =AVERAGEIF('Benchmarking Data'!F2:F131, 'Feature List'!B6, 'Benchmarking Data'!J2:J131) -> 7.6 | I6: ='Feature List'!C6 -> 7 | J6: =VLOOKUP('Feature List'!B6, 'Gap Analysis'!A2:F26, 4, FALSE) -> Gap | K6: =VLOOKUP('Feature List'!B6, 'Gap Analysis'!A2:F26, 6, FALSE) -> High | L6: {=INDEX('Benchmarking Data'!AB2:AB131, MATCH('Feature List'!B6, 'Benchmarking Data'!F2:F131, 0))} -> Promote & Monetize
A7: ='Feature List'!B7 -> Interactive Drill-Downs | B7: {=INDEX('Benchmarking Data'!G2:G131, MATCH('Feature List'!B7, 'Benchmarking Data'!F2:F131, 0))} -> Available | C7: {=INDEX('Benchmarking Data'!H2:H131, MATCH(1, ('Benchmarking Data'!F2:F131='Feature List'!B7)*('Benchmarking Data'!C2:C131='Competitor List'!A2), 0))} -> Partial | D7: {=INDEX('Benchmarking Data'!H2:H131, MATCH(1, ('Benchmarking Data'!F2:F131='Feature List'!B7)*('Benchmarking Data'!C2:C131='Competitor List'!A3), 0))} -> Partial | E7: {=INDEX('Benchmarking Data'!H2:H131, MATCH(1, ('Benchmarking Data'!F2:F131='Feature List'!B7)*('Benchmarking Data'!C2:C131='Competitor List'!A4), 0))} -> Partial | F7: {=INDEX('Benchmarking Data'!H2:H131, MATCH(1, ('Benchmarking Data'!F2:F131='Feature List'!B7)*('Benchmarking Data'!C2:C131='Competitor List'!A5), 0))} -> Available | G7: {=INDEX('Benchmarking Data'!H2:H131, MATCH(1, ('Benchmarking Data'!F2:F131='Feature List'!B7)*('Benchmarking Data'!C2:C131='Competitor List'!A6), 0))} -> Partial | H7: =AVERAGEIF('Benchmarking Data'!F2:F131, 'Feature List'!B7, 'Benchmarking Data'!J2:J131) -> 7.8 | I7: ='Feature List'!C7 -> 7 | J7: =VLOOKUP('Feature List'!B7, 'Gap Analysis'!A2:F26, 4, FALSE) -> Gap | K7: =VLOOKUP('Feature List'!B7, 'Gap Analysis'!A2:F26, 6, FALSE) -> High | L7: {=INDEX('Benchmarking Data'!AB2:AB131, MATCH('Feature List'!B7, 'Benchmarking Data'!F2:F131, 0))} -> Maintain Advantage
A8: ='Feature List'!B8 -> Predictive Anomaly Detection | B8: {=INDEX('Benchmarking Data'!G2:G131, MATCH('Feature List'!B8, 'Benchmarking Data'!F2:F131, 0))} -> Available | C8: {=INDEX('Benchmarking Data'!H2:H131, MATCH(1, ('Benchmarking Data'!F2:F131='Feature List'!B8)*('Benchmarking Data'!C2:C131='Competitor List'!A2), 0))} -> Available | D8: {=INDEX('Benchmarking Data'!H2:H131, MATCH(1, ('Benchmarking Data'!F2:F131='Feature List'!B8)*('Benchmarking Data'!C2:C131='Competitor List'!A3), 0))} -> Partial | E8: {=INDEX('Benchmarking Data'!H2:H131, MATCH(1, ('Benchmarking Data'!F2:F131='Feature List'!B8)*('Benchmarking Data'!C2:C131='Competitor List'!A4), 0))} -> Partial | F8: {=INDEX('Benchmarking Data'!H2:H131, MATCH(1, ('Benchmarking Data'!F2:F131='Feature List'!B8)*('Benchmarking Data'!C2:C131='Competitor List'!A5), 0))} -> Partial | G8: {=INDEX('Benchmarking Data'!H2:H131, MATCH(1, ('Benchmarking Data'!F2:F131='Feature List'!B8)*('Benchmarking Data'!C2:C131='Competitor List'!A6), 0))} -> Available | H8: =AVERAGEIF('Benchmarking Data'!F2:F131, 'Feature List'!B8, 'Benchmarking Data'!J2:J131) -> 5.8 | I8: ='Feature List'!C8 -> 6 | J8: =VLOOKUP('Feature List'!B8, 'Gap Analysis'!A2:F26, 4, FALSE) -> Gap | K8: =VLOOKUP('Feature List'!B8, 'Gap Analysis'!A2:F26, 6, FALSE) -> High | L8: {=INDEX('Benchmarking Data'!AB2:AB131, MATCH('Feature List'!B8, 'Benchmarking Data'!F2:F131, 0))} -> Monitor Market
A9: ='Feature List'!B9 -> Automated Insight Generation | B9: {=INDEX('Benchmarking Data'!G2:G131, MATCH('Feature List'!B9, 'Benchmarking Data'!F2:F131, 0))} -> Available | C9: {=INDEX('Benchmarking Data'!H2:H131, MATCH(1, ('Benchmarking Data'!F2:F131='Feature List'!B9)*('Benchmarking Data'!C2:C131='Competitor List'!A2), 0))} -> Available | D9: {=INDEX('Benchmarking Data'!H2:H131, MATCH(1, ('Benchmarking Data'!F2:F131='Feature List'!B9)*('Benchmarking Data'!C2:C131='Competitor List'!A3), 0))} -> Partial | E9: {=INDEX('Benchmarking Data'!H2:H131, MATCH(1, ('Benchmarking Data'!F2:F131='Feature List'!B9)*('Benchmarking Data'!C2:C131='Competitor List'!A4), 0))} -> Not Available | F9: {=INDEX('Benchmarking Data'!H2:H131, MATCH(1, ('Benchmarking Data'!F2:F131='Feature List'!B9)*('Benchmarking Data'!C2:C131='Competitor List'!A5), 0))} -> Available | G9: {=INDEX('Benchmarking Data'!H2:H131, MATCH(1, ('Benchmarking Data'!F2:F131='Feature List'!B9)*('Benchmarking Data'!C2:C131='Competitor List'!A6), 0))} -> Partial | H9: =AVERAGEIF('Benchmarking Data'!F2:F131, 'Feature List'!B9, 'Benchmarking Data'!J2:J131) -> 8.8 | I9: ='Feature List'!C9 -> 10 | J9: =VLOOKUP('Feature List'!B9, 'Gap Analysis'!A2:F26, 4, FALSE) -> Gap | K9: =VLOOKUP('Feature List'!B9, 'Gap Analysis'!A2:F26, 6, FALSE) -> Medium | L9: {=INDEX('Benchmarking Data'!AB2:AB131, MATCH('Feature List'!B9, 'Benchmarking Data'!F2:F131, 0))} -> Monitor Market
A10: ='Feature List'!B10 -> Natural Language Querying (NLQ) | B10: {=INDEX('Benchmarking Data'!G2:G131, MATCH('Feature List'!B10, 'Benchmarking Data'!F2:F131, 0))} -> Partial | C10: {=INDEX('Benchmarking Data'!H2:H131, MATCH(1, ('Benchmarking Data'!F2:F131='Feature List'!B10)*('Benchmarking Data'!C2:C131='Competitor List'!A2), 0))} -> Partial | D10: {=INDEX('Benchmarking Data'!H2:H131, MATCH(1, ('Benchmarking Data'!F2:F131='Feature List'!B10)*('Benchmarking Data'!C2:C131='Competitor List'!A3), 0))} -> Partial | E10: {=INDEX('Benchmarking Data'!H2:H131, MATCH(1, ('Benchmarking Data'!F2:F131='Feature List'!B10)*('Benchmarking Data'!C2:C131='Competitor List'!A4), 0))} -> Not Available | F10: {=INDEX('Benchmarking Data'!H2:H131, MATCH(1, ('Benchmarking Data'!F2:F131='Feature List'!B10)*('Benchmarking Data'!C2:C131='Competitor List'!A5), 0))} -> Not Available | G10: {=INDEX('Benchmarking Data'!H2:H131, MATCH(1, ('Benchmarking Data'!F2:F131='Feature List'!B10)*('Benchmarking Data'!C2:C131='Competitor List'!A6), 0))} -> Available | H10: =AVERAGEIF('Benchmarking Data'!F2:F131, 'Feature List'!B10, 'Benchmarking Data'!J2:J131) -> 7 | I10: ='Feature List'!C10 -> 6 | J10: =VLOOKUP('Feature List'!B10, 'Gap Analysis'!A2:F26, 4, FALSE) -> Gap | K10: =VLOOKUP('Feature List'!B10, 'Gap Analysis'!A2:F26, 6, FALSE) -> High | L10: {=INDEX('Benchmarking Data'!AB2:AB131, MATCH('Feature List'!B10, 'Benchmarking Data'!F2:F131, 0))} -> Monitor Market
A11: ='Feature List'!B11 -> Forecasting & Trend Projection | B11: {=INDEX('Benchmarking Data'!G2:G131, MATCH('Feature List'!B11, 'Benchmarking Data'!F2:F131, 0))} -> Available | C11: {=INDEX('Benchmarking Data'!H2:H131, MATCH(1, ('Benchmarking Data'!F2:F131='Feature List'!B11)*('Benchmarking Data'!C2:C131='Competitor List'!A2), 0))} -> Available | D11: {=INDEX('Benchmarking Data'!H2:H131, MATCH(1, ('Benchmarking Data'!F2:F131='Feature List'!B11)*('Benchmarking Data'!C2:C131='Competitor List'!A3), 0))} -> Partial | E11: {=INDEX('Benchmarking Data'!H2:H131, MATCH(1, ('Benchmarking Data'!F2:F131='Feature List'!B11)*('Benchmarking Data'!C2:C131='Competitor List'!A4), 0))} -> Not Available | F11: {=INDEX('Benchmarking Data'!H2:H131, MATCH(1, ('Benchmarking Data'!F2:F131='Feature List'!B11)*('Benchmarking Data'!C2:C131='Competitor List'!A5), 0))} -> Not Available | G11: {=INDEX('Benchmarking Data'!H2:H131, MATCH(1, ('Benchmarking Data'!F2:F131='Feature List'!B11)*('Benchmarking Data'!C2:C131='Competitor List'!A6), 0))} -> Available | H11: =AVERAGEIF('Benchmarking Data'!F2:F131, 'Feature List'!B11, 'Benchmarking Data'!J2:J131) -> 7.8 | I11: ='Feature List'!C11 -> 10 | J11: =VLOOKUP('Feature List'!B11, 'Gap Analysis'!A2:F26, 4, FALSE) -> No Gap | K11: =VLOOKUP('Feature List'!B11, 'Gap Analysis'!A2:F26, 6, FALSE) -> Low | L11: {=INDEX('Benchmarking Data'!AB2:AB131, MATCH('Feature List'!B11, 'Benchmarking Data'!F2:F131, 0))} -> Monitor Market
A12: ='Feature List'!B12 -> Smart Alerting & Triggers | B12: {=INDEX('Benchmarking Data'!G2:G131, MATCH('Feature List'!B12, 'Benchmarking Data'!F2:F131, 0))} -> Available | C12: {=INDEX('Benchmarking Data'!H2:H131, MATCH(1, ('Benchmarking Data'!F2:F131='Feature List'!B12)*('Benchmarking Data'!C2:C131='Competitor List'!A2), 0))} -> Available | D12: {=INDEX('Benchmarking Data'!H2:H131, MATCH(1, ('Benchmarking Data'!F2:F131='Feature List'!B12)*('Benchmarking Data'!C2:C131='Competitor List'!A3), 0))} -> Not Available | E12: {=INDEX('Benchmarking Data'!H2:H131, MATCH(1, ('Benchmarking Data'!F2:F131='Feature List'!B12)*('Benchmarking Data'!C2:C131='Competitor List'!A4), 0))} -> Partial | F12: {=INDEX('Benchmarking Data'!H2:H131, MATCH(1, ('Benchmarking Data'!F2:F131='Feature List'!B12)*('Benchmarking Data'!C2:C131='Competitor List'!A5), 0))} -> Not Available | G12: {=INDEX('Benchmarking Data'!H2:H131, MATCH(1, ('Benchmarking Data'!F2:F131='Feature List'!B12)*('Benchmarking Data'!C2:C131='Competitor List'!A6), 0))} -> Available | H12: =AVERAGEIF('Benchmarking Data'!F2:F131, 'Feature List'!B12, 'Benchmarking Data'!J2:J131) -> 6.8 | I12: ='Feature List'!C12 -> 9 | J12: =VLOOKUP('Feature List'!B12, 'Gap Analysis'!A2:F26, 4, FALSE) -> Gap | K12: =VLOOKUP('Feature List'!B12, 'Gap Analysis'!A2:F26, 6, FALSE) -> High | L12: {=INDEX('Benchmarking Data'!AB2:AB131, MATCH('Feature List'!B12, 'Benchmarking Data'!F2:F131, 0))} -> Monitor Market
A13: ='Feature List'!B13 -> REST API & Webhooks | B13: {=INDEX('Benchmarking Data'!G2:G131, MATCH('Feature List'!B13, 'Benchmarking Data'!F2:F131, 0))} -> Available | C13: {=INDEX('Benchmarking Data'!H2:H131, MATCH(1, ('Benchmarking Data'!F2:F131='Feature List'!B13)*('Benchmarking Data'!C2:C131='Competitor List'!A2), 0))} -> Available | D13: {=INDEX('Benchmarking Data'!H2:H131, MATCH(1, ('Benchmarking Data'!F2:F131='Feature List'!B13)*('Benchmarking Data'!C2:C131='Competitor List'!A3), 0))} -> Partial | E13: {=INDEX('Benchmarking Data'!H2:H131, MATCH(1, ('Benchmarking Data'!F2:F131='Feature List'!B13)*('Benchmarking Data'!C2:C131='Competitor List'!A4), 0))} -> Available | F13: {=INDEX('Benchmarking Data'!H2:H131, MATCH(1, ('Benchmarking Data'!F2:F131='Feature List'!B13)*('Benchmarking Data'!C2:C131='Competitor List'!A5), 0))} -> Available | G13: {=INDEX('Benchmarking Data'!H2:H131, MATCH(1, ('Benchmarking Data'!F2:F131='Feature List'!B13)*('Benchmarking Data'!C2:C131='Competitor List'!A6), 0))} -> Partial | H13: =AVERAGEIF('Benchmarking Data'!F2:F131, 'Feature List'!B13, 'Benchmarking Data'!J2:J131) -> 7.2 | I13: ='Feature List'!C13 -> 6 | J13: =VLOOKUP('Feature List'!B13, 'Gap Analysis'!A2:F26, 4, FALSE) -> Gap | K13: =VLOOKUP('Feature List'!B13, 'Gap Analysis'!A2:F26, 6, FALSE) -> High | L13: {=INDEX('Benchmarking Data'!AB2:AB131, MATCH('Feature List'!B13, 'Benchmarking Data'!F2:F131, 0))} -> Monitor Market
A14: ='Feature List'!B14 -> Pre-built Salesforce Connector | B14: {=INDEX('Benchmarking Data'!G2:G131, MATCH('Feature List'!B14, 'Benchmarking Data'!F2:F131, 0))} -> Available | C14: {=INDEX('Benchmarking Data'!H2:H131, MATCH(1, ('Benchmarking Data'!F2:F131='Feature List'!B14)*('Benchmarking Data'!C2:C131='Competitor List'!A2), 0))} -> Not Available | D14: {=INDEX('Benchmarking Data'!H2:H131, MATCH(1, ('Benchmarking Data'!F2:F131='Feature List'!B14)*('Benchmarking Data'!C2:C131='Competitor List'!A3), 0))} -> Partial | E14: {=INDEX('Benchmarking Data'!H2:H131, MATCH(1, ('Benchmarking Data'!F2:F131='Feature List'!B14)*('Benchmarking Data'!C2:C131='Competitor List'!A4), 0))} -> Available | F14: {=INDEX('Benchmarking Data'!H2:H131, MATCH(1, ('Benchmarking Data'!F2:F131='Feature List'!B14)*('Benchmarking Data'!C2:C131='Competitor List'!A5), 0))} -> Partial | G14: {=INDEX('Benchmarking Data'!H2:H131, MATCH(1, ('Benchmarking Data'!F2:F131='Feature List'!B14)*('Benchmarking Data'!C2:C131='Competitor List'!A6), 0))} -> Partial | H14: =AVERAGEIF('Benchmarking Data'!F2:F131, 'Feature List'!B14, 'Benchmarking Data'!J2:J131) -> 7.6 | I14: ='Feature List'!C14 -> 6 | J14: =VLOOKUP('Feature List'!B14, 'Gap Analysis'!A2:F26, 4, FALSE) -> Gap | K14: =VLOOKUP('Feature List'!B14, 'Gap Analysis'!A2:F26, 6, FALSE) -> High | L14: {=INDEX('Benchmarking Data'!AB2:AB131, MATCH('Feature List'!B14, 'Benchmarking Data'!F2:F131, 0))} -> Promote & Monetize
A15: ='Feature List'!B15 -> Snowflake & BigQuery Sync | B15: {=INDEX('Benchmarking Data'!G2:G131, MATCH('Feature List'!B15, 'Benchmarking Data'!F2:F131, 0))} -> Available | C15: {=INDEX('Benchmarking Data'!H2:H131, MATCH(1, ('Benchmarking Data'!F2:F131='Feature List'!B15)*('Benchmarking Data'!C2:C131='Competitor List'!A2), 0))} -> Partial | D15: {=INDEX('Benchmarking Data'!H2:H131, MATCH(1, ('Benchmarking Data'!F2:F131='Feature List'!B15)*('Benchmarking Data'!C2:C131='Competitor List'!A3), 0))} -> Available | E15: {=INDEX('Benchmarking Data'!H2:H131, MATCH(1, ('Benchmarking Data'!F2:F131='Feature List'!B15)*('Benchmarking Data'!C2:C131='Competitor List'!A4), 0))} -> Partial | F15: {=INDEX('Benchmarking Data'!H2:H131, MATCH(1, ('Benchmarking Data'!F2:F131='Feature List'!B15)*('Benchmarking Data'!C2:C131='Competitor List'!A5), 0))} -> Partial | G15: {=INDEX('Benchmarking Data'!H2:H131, MATCH(1, ('Benchmarking Data'!F2:F131='Feature List'!B15)*('Benchmarking Data'!C2:C131='Competitor List'!A6), 0))} -> Partial | H15: =AVERAGEIF('Benchmarking Data'!F2:F131, 'Feature List'!B15, 'Benchmarking Data'!J2:J131) -> 7.2 | I15: ='Feature List'!C15 -> 6 | J15: =VLOOKUP('Feature List'!B15, 'Gap Analysis'!A2:F26, 4, FALSE) -> Gap | K15: =VLOOKUP('Feature List'!B15, 'Gap Analysis'!A2:F26, 6, FALSE) -> High | L15: {=INDEX('Benchmarking Data'!AB2:AB131, MATCH('Feature List'!B15, 'Benchmarking Data'!F2:F131, 0))} -> Maintain Advantage
